Workbook

Sheet Shiftlab
A1: Area Name | B1: District Name | C1: Store | D1: Employee | E1: Title | F1: Date | G1: Scheduled In | H1: Scheduled Out | I1: Actual In | J1: Actual Out | K1: Hours Scheduled | L1: Hours Worked | M1: Breaks | N1: Break Minutes | O1: Event | P1: Camera In | Q1: Camera Out | R1: Total Time | S1: Showroom Time | T1: Backroom Time | U1: Break | V1: Monitored
A2: Central | B2: DFW East | C2: Golden Triangle | D2: JYE PECHACEK | E2: MOBILE ASSOCIATE | F2: 46296 | G2: 0.39583333 | H2: 0.75 | I2: 0.401875 | J2: 0.73311343 | K2: 8 | L2: 7.3669444 | M2: 1 | N2: 34.966667 | O2: Early Clock Out | P2: {=_xlfn.XLOOKUP(1,(Rebiz!A:A=Table2[[#This Row],[Employee]])*(Rebiz!C:C=Table2[[#This Row],[Date]]),Rebiz!E:E,"")} -> 46296.403 | Q2: {=_xlfn.XLOOKUP(1,(Rebiz!A:A=Table2[[#This Row],[Employee]])*(Rebiz!C:C=Table2[[#This Row],[Date]]),Rebiz!F:F,"")} -> 46296.737 | R2: {=_xlfn.XLOOKUP(1,(Rebiz!A:A=Table2[[#This Row],[Employee]])*(Rebiz!C:C=Table2[[#This Row],[Date]]),Rebiz!G:G,"")} -> 7:36 | S2: {=_xlfn.XLOOKUP(1,(Rebiz!A:A=Table2[[#This Row],[Employee]])*(Rebiz!C:C=Table2[[#This Row],[Date]]),Rebiz!H:H,"")} -> 7:36 | T2: {=_xlfn.XLOOKUP(1,(Rebiz!A:A=Table2[[#This Row],[Employee]])*(Rebiz!C:C=Table2[[#This Row],[Date]]),Rebiz!I:I,"")} -> 0:0 | U2: {=_xlfn.XLOOKUP(1,(Rebiz!A:A=Table2[[#This Row],[Employee]])*(Rebiz!C:C=Table2[[#This Row],[Date]]),Rebiz!J:J,"")} -> 0:25 | V2: {=_xlfn.XLOOKUP(1,(Rebiz!A:A=Table2[[#This Row],[Employee]])*(Rebiz!C:C=Table2[[#This Row],[Date]]),Rebiz!K:K,"")} -> Y
A3: Central | B3: DFW North | C3: Seventh Ave | D3: SUZANNE REINA | E3: MOBILE ASSOCIATE | F3: 46296 | G3: 0.41666667 | H3: 0.75 | I3: 0.41469907 | J3: 0.73038194 | K3: 7.5 | L3: 6.7869444 | M3: 1 | N3: 47.366667 | O3: Early Clock Out | P3: {=_xlfn.XLOOKUP(1,(Rebiz!A:A=Table2[[#This Row],[Employee]])*(Rebiz!C:C=Table2[[#This Row],[Date]]),Rebiz!E:E,"")} | Q3: {=_xlfn.XLOOKUP(1,(Rebiz!A:A=Table2[[#This Row],[Employee]])*(Rebiz!C:C=Table2[[#This Row],[Date]]),Rebiz!F:F,"")} | R3: {=_xlfn.XLOOKUP(1,(Rebiz!A:A=Table2[[#This Row],[Employee]])*(Rebiz!C:C=Table2[[#This Row],[Date]]),Rebiz!G:G,"")} | S3: {=_xlfn.XLOOKUP(1,(Rebiz!A:A=Table2[[#This Row],[Employee]])*(Rebiz!C:C=Table2[[#This Row],[Date]]),Rebiz!H:H,"")} | T3: {=_xlfn.XLOOKUP(1,(Rebiz!A:A=Table2[[#This Row],[Employee]])*(Rebiz!C:C=Table2[[#This Row],[Date]]),Rebiz!I:I,"")} | U3: {=_xlfn.XLOOKUP(1,(Rebiz!A:A=Table2[[#This Row],[Employee]])*(Rebiz!C:C=Table2[[#This Row],[Date]]),Rebiz!J:J,"")} | V3: {=_xlfn.XLOOKUP(1,(Rebiz!A:A=Table2[[#This Row],[Employee]])*(Rebiz!C:C=Table2[[#This Row],[Date]]),Rebiz!K:K,"")}
A4: Central | B4: South TX/RGV | C4: Kingsville | D4: ROEL GARCIA | E4: MOBILE ASSOCIATE | F4: 46296 | G4: 0.45833333 | H4: 0.79166667 | I4: 0.46592593 | J4: 0.73820602 | K4: 7 | L4: 5.5266667 | M4: 1 | N4: 60.483333 | O4: Late Clock In, Early Clock Out | P4: {=_xlfn.XLOOKUP(1,(Rebiz!A:A=Table2[[#This Row],[Employee]])*(Rebiz!C:C=Table2[[#This Row],[Date]]),Rebiz!E:E,"")} -> 46296.467 | Q4: {=_xlfn.XLOOKUP(1,(Rebiz!A:A=Table2[[#This Row],[Employee]])*(Rebiz!C:C=Table2[[#This Row],[Date]]),Rebiz!F:F,"")} -> 46296.74 | R4: {=_xlfn.XLOOKUP(1,(Rebiz!A:A=Table2[[#This Row],[Employee]])*(Rebiz!C:C=Table2[[#This Row],[Date]]),Rebiz!G:G,"")} -> 6:33 | S4: {=_xlfn.XLOOKUP(1,(Rebiz!A:A=Table2[[#This Row],[Employee]])*(Rebiz!C:C=Table2[[#This Row],[Date]]),Rebiz!H:H,"")} -> 6:21 | T4: {=_xlfn.XLOOKUP(1,(Rebiz!A:A=Table2[[#This Row],[Employee]])*(Rebiz!C:C=Table2[[#This Row],[Date]]),Rebiz!I:I,"")} -> 0:12 | U4: {=_xlfn.XLOOKUP(1,(Rebiz!A:A=Table2[[#This Row],[Employee]])*(Rebiz!C:C=Table2[[#This Row],[Date]]),Rebiz!J:J,"")} -> 0:0 | V4: {=_xlfn.XLOOKUP(1,(Rebiz!A:A=Table2[[#This Row],[Employee]])*(Rebiz!C:C=Table2[[#This Row],[Date]]),Rebiz!K:K,"")} -> Y
A5: Central | B5: KS/OK | C5: Garth Brooks Blvd | D5: SILAS LITTLE | E5: MOBILE ASSOCIATE | F5: 46296 | G5: 0.5 | H5: 0.85416667 | I5: 0.51321759 | J5: 0.75796296 | K5: 8 | L5: 5.3672222 | M5: 1 | N5: 30.4 | O5: Late Clock In, Early Clock Out | P5: {=_xlfn.XLOOKUP(1,(Rebiz!A:A=Table2[[#This Row],[Employee]])*(Rebiz!C:C=Table2[[#This Row],[Date]]),Rebiz!E:E,"")} | Q5: {=_xlfn.XLOOKUP(1,(Rebiz!A:A=Table2[[#This Row],[Employee]])*(Rebiz!C:C=Table2[[#This Row],[Date]]),Rebiz!F:F,"")} | R5: {=_xlfn.XLOOKUP(1,(Rebiz!A:A=Table2[[#This Row],[Employee]])*(Rebiz!C:C=Table2[[#This Row],[Date]]),Rebiz!G:G,"")} | S5: {=_xlfn.XLOOKUP(1,(Rebiz!A:A=Table2[[#This Row],[Employee]])*(Rebiz!C:C=Table2[[#This Row],[Date]]),Rebiz!H:H,"")} | T5: {=_xlfn.XLOOKUP(1,(Rebiz!A:A=Table2[[#This Row],[Employee]])*(Rebiz!C:C=Table2[[#This Row],[Date]]),Rebiz!I:I,"")} | U5: {=_xlfn.XLOOKUP(1,(Rebiz!A:A=Table2[[#This Row],[Employee]])*(Rebiz!C:C=Table2[[#This Row],[Date]]),Rebiz!J:J,"")} | V5: {=_xlfn.XLOOKUP(1,(Rebiz!A:A=Table2[[#This Row],[Employee]])*(Rebiz!C:C=Table2[[#This Row],[Date]]),Rebiz!K:K,"")}
A6: Central | B6: South TX/RGV | C6: Rockport | D6: ETHAN DUGGER | E6: MOBILE ASSOCIATE | F6: 46296 | I6: 0.41284722 | J6: 0.7309375 | K6: 0 | L6: 6.9158333 | M6: 1 | N6: 43.1 | O6: Not Scheduled | P6: {=_xlfn.XLOOKUP(1,(Rebiz!A:A=Table2[[#This Row],[Employee]])*(Rebiz!C:C=Table2[[#This Row],[Date]]),Rebiz!E:E,"")} -> 46296.414 | Q6: {=_xlfn.XLOOKUP(1,(Rebiz!A:A=Table2[[#This Row],[Employee]])*(Rebiz!C:C=Table2[[#This Row],[Date]]),Rebiz!F:F,"")} -> 46296.742 | R6: {=_xlfn.XLOOKUP(1,(Rebiz!A:A=Table2[[#This Row],[Employee]])*(Rebiz!C:C=Table2[[#This Row],[Date]]),Rebiz!G:G,"")} -> 7:52 | S6: {=_xlfn.XLOOKUP(1,(Rebiz!A:A=Table2[[#This Row],[Employee]])*(Rebiz!C:C=Table2[[#This Row],[Date]]),Rebiz!H:H,"")} -> 1:34 | T6: {=_xlfn.XLOOKUP(1,(Rebiz!A:A=Table2[[#This Row],[Employee]])*(Rebiz!C:C=Table2[[#This Row],[Date]]),Rebiz!I:I,"")} -> 6:18 | U6: {=_xlfn.XLOOKUP(1,(Rebiz!A:A=Table2[[#This Row],[Employee]])*(Rebiz!C:C=Table2[[#This Row],[Date]]),Rebiz!J:J,"")} -> 0:0 | V6: {=_xlfn.XLOOKUP(1,(Rebiz!A:A=Table2[[#This Row],[Employee]])*(Rebiz!C:C=Table2[[#This Row],[Date]]),Rebiz!K:K,"")} -> Y
A7: Central | B7: South TX/RGV | C7: Viejo | D7: JOAQUIN VILLARREAL | E7: MOBILE ASSOCIATE | F7: 46296 | G7: 0.39583333 | H7: 0.75 | I7: 0.40409722 | J7: 0.75050926 | K7: 8 | L7: 7.7133333 | M7: 1 | N7: 36.033333 | O7: Late Clock In | P7: {=_xlfn.XLOOKUP(1,(Rebiz!A:A=Table2[[#This Row],[Employee]])*(Rebiz!C:C=Table2[[#This Row],[Date]]),Rebiz!E:E,"")} -> 46296.399 | Q7: {=_xlfn.XLOOKUP(1,(Rebiz!A:A=Table2[[#This Row],[Employee]])*(Rebiz!C:C=Table2[[#This Row],[Date]]),Rebiz!F:F,"")} -> 46296.756 | R7: {=_xlfn.XLOOKUP(1,(Rebiz!A:A=Table2[[#This Row],[Employee]])*(Rebiz!C:C=Table2[[#This Row],[Date]]),Rebiz!G:G,"")} -> 8:34 | S7: {=_xlfn.XLOOKUP(1,(Rebiz!A:A=Table2[[#This Row],[Employee]])*(Rebiz!C:C=Table2[[#This Row],[Date]]),Rebiz!H:H,"")} -> 8:34 | T7: {=_xlfn.XLOOKUP(1,(Rebiz!A:A=Table2[[#This Row],[Employee]])*(Rebiz!C:C=Table2[[#This Row],[Date]]),Rebiz!I:I,"")} -> 0:0 | U7: {=_xlfn.XLOOKUP(1,(Rebiz!A:A=Table2[[#This Row],[Employee]])*(Rebiz!C:C=Table2[[#This Row],[Date]]),Rebiz!J:J,"")} -> 0:0 | V7: {=_xlfn.XLOOKUP(1,(Rebiz!A:A=Table2[[#This Row],[Employee]])*(Rebiz!C:C=Table2[[#This Row],[Date]]),Rebiz!K:K,"")} -> Y
A8: Central | B8: DFW North | C8: Seventh Ave | D8: LOGAN SMITH | E8: MOBILE ASSOCIATE | F8: 46296 | I8: 0.48005787 | J8: 0.73017361 | K8: 0 | L8: 5.0008333 | M8: 1 | N8: 60.116667 | O8: Not Scheduled | P8: {=_xlfn.XLOOKUP(1,(Rebiz!A:A=Table2[[#This Row],[Employee]])*(Rebiz!C:C=Table2[[#This Row],[Date]]),Rebiz!E:E,"")} -> 46296.483 | Q8: {=_xlfn.XLOOKUP(1,(Rebiz!A:A=Table2[[#This Row],[Employee]])*(Rebiz!C:C=Table2[[#This Row],[Date]]),Rebiz!F:F,"")} -> 46296.733 | R8: {=_xlfn.XLOOKUP(1,(Rebiz!A:A=Table2[[#This Row],[Employee]])*(Rebiz!C:C=Table2[[#This Row],[Date]]),Rebiz!G:G,"")} -> 5:2 | S8: {=_xlfn.XLOOKUP(1,(Rebiz!A:A=Table2[[#This Row],[Employee]])*(Rebiz!C:C=Table2[[#This Row],[Date]]),Rebiz!H:H,"")} -> 5:2 | T8: {=_xlfn.XLOOKUP(1,(Rebiz!A:A=Table2[[#This Row],[Employee]])*(Rebiz!C:C=Table2[[#This Row],[Date]]),Rebiz!I:I,"")} -> 0:0 | U8: {=_xlfn.XLOOKUP(1,(Rebiz!A:A=Table2[[#This Row],[Employee]])*(Rebiz!C:C=Table2[[#This Row],[Date]]),Rebiz!J:J,"")} -> 0:59 | V8: {=_xlfn.XLOOKUP(1,(Rebiz!A:A=Table2[[#This Row],[Employee]])*(Rebiz!C:C=Table2[[#This Row],[Date]]),Rebiz!K:K,"")} -> Y
A9: Central | B9: West Texas | C9: Olton | D9: NANCY BENAVIDES | E9: MOBILE ASSOCIATE | F9: 46296 | G9: 0.54166667 | H9: 0.85416667 | I9: 0.5424537 | J9: 0.85059028 | K9: 7 | L9: 6.3763889 | M9: 1 | N9: 61.133333 | O9: On Time | P9: {=_xlfn.XLOOKUP(1,(Rebiz!A:A=Table2[[#This Row],[Employee]])*(Rebiz!C:C=Table2[[#This Row],[Date]]),Rebiz!E:E,"")} -> 46296.545 | Q9: {=_xlfn.XLOOKUP(1,(Rebiz!A:A=Table2[[#This Row],[Employee]])*(Rebiz!C:C=Table2[[#This Row],[Date]]),Rebiz!F:F,"")} -> 46296.852 | R9: {=_xlfn.XLOOKUP(1,(Rebiz!A:A=Table2[[#This Row],[Employee]])*(Rebiz!C:C=Table2[[#This Row],[Date]]),Rebiz!G:G,"")} -> 6:10 | S9: {=_xlfn.XLOOKUP(1,(Rebiz!A:A=Table2[[#This Row],[Employee]])*(Rebiz!C:C=Table2[[#This Row],[Date]]),Rebiz!H:H,"")} -> 5:55 | T9: {=_xlfn.XLOOKUP(1,(Rebiz!A:A=Table2[[#This Row],[Employee]])*(Rebiz!C:C=Table2[[#This Row],[Date]]),Rebiz!I:I,"")} -> 0:15 | U9: {=_xlfn.XLOOKUP(1,(Rebiz!A:A=Table2[[#This Row],[Employee]])*(Rebiz!C:C=Table2[[#This Row],[Date]]),Rebiz!J:J,"")} -> 1:12 | V9: {=_xlfn.XLOOKUP(1,(Rebiz!A:A=Table2[[#This Row],[Employee]])*(Rebiz!C:C=Table2[[#This Row],[Date]]),Rebiz!K:K,"")} -> Y
A10: Central | B10: MO/IA/NE | C10: Virginia Avenue | D10: GUSTAVO CUATLACUATL | E10: MOBILE ASSOCIATE | F10: 46296 | G10: 0.52083333 | H10: 0.85416667 | K10: 7.5 | L10: 0 | M10: 0 | N10: 0 | O10: No Show | P10: {=_xlfn.XLOOKUP(1,(Rebiz!A:A=Table2[[#This Row],[Employee]])*(Rebiz!C:C=Table2[[#This Row],[Date]]),Rebiz!E:E,"")} | Q10: {=_xlfn.XLOOKUP(1,(Rebiz!A:A=Table2[[#This Row],[Employee]])*(Rebiz!C:C=Table2[[#This Row],[Date]]),Rebiz!F:F,"")} | R10: {=_xlfn.XLOOKUP(1,(Rebiz!A:A=Table2[[#This Row],[Employee]])*(Rebiz!C:C=Table2[[#This Row],[Date]]),Rebiz!G:G,"")} | S10: {=_xlfn.XLOOKUP(1,(Rebiz!A:A=Table2[[#This Row],[Employee]])*(Rebiz!C:C=Table2[[#This Row],[Date]]),Rebiz!H:H,"")} | T10: {=_xlfn.XLOOKUP(1,(Rebiz!A:A=Table2[[#This Row],[Employee]])*(Rebiz!C:C=Table2[[#This Row],[Date]]),Rebiz!I:I,"")} | U10: {=_xlfn.XLOOKUP(1,(Rebiz!A:A=Table2[[#This Row],[Employee]])*(Rebiz!C:C=Table2[[#This Row],[Date]]),Rebiz!J:J,"")} | V10: {=_xlfn.XLOOKUP(1,(Rebiz!A:A=Table2[[#This Row],[Employee]])*(Rebiz!C:C=Table2[[#This Row],[Date]]),Rebiz!K:K,"")}
A11: Central | B11: South TX/RGV | C11: Beeville | D11: ALBERT GARCIA | E11: MOBILE ASSOCIATE | F11: 46296 | G11: 0.45833333 | H11: 0.75 | I11: 0.45833333 | J11: 0.86954861 | K11: 6.5 | L11: 9.0927778 | M11: 1 | N11: 46.583333 | O11: Late Clock Out | P11: {=_xlfn.XLOOKUP(1,(Rebiz!A:A=Table2[[#This Row],[Employee]])*(Rebiz!C:C=Table2[[#This Row],[Date]]),Rebiz!E:E,"")} -> 46296.459 | Q11: {=_xlfn.XLOOKUP(1,(Rebiz!A:A=Table2[[#This Row],[Employee]])*(Rebiz!C:C=Table2[[#This Row],[Date]]),Rebiz!F:F,"")} -> 46296.872 | R11: {=_xlfn.XLOOKUP(1,(Rebiz!A:A=Table2[[#This Row],[Employee]])*(Rebiz!C:C=Table2[[#This Row],[Date]]),Rebiz!G:G,"")} -> 9:10 | S11: {=_xlfn.XLOOKUP(1,(Rebiz!A:A=Table2[[#This Row],[Employee]])*(Rebiz!C:C=Table2[[#This Row],[Date]]),Rebiz!H:H,"")} -> 7:13 | T11: {=_xlfn.XLOOKUP(1,(Rebiz!A:A=Table2[[#This Row],[Employee]])*(Rebiz!C:C=Table2[[#This Row],[Date]]),Rebiz!I:I,"")} -> 1:57 | U11: {=_xlfn.XLOOKUP(1,(Rebiz!A:A=Table2[[#This Row],[Employee]])*(Rebiz!C:C=Table2[[#This Row],[Date]]),Rebiz!J:J,"")} -> 0:45 | V11: {=_xlfn.XLOOKUP(1,(Rebiz!A:A=Table2[[#This Row],[Employee]])*(Rebiz!C:C=Table2[[#This Row],[Date]]),Rebiz!K:K,"")} -> Y
A12: Central | B12: SA South | C12: Palo Alto | D12: DANIELLE VILLARREAL | E12: MOBILE ASSOCIATE | F12: 46296 | I12: 0.47533565 | J12: 0.73929398 | K12: 0 | L12: 5.7925 | M12: 1 | N12: 32.55 | O12: Not Scheduled | P12: {=_xlfn.XLOOKUP(1,(Rebiz!A:A=Table2[[#This Row],[Employee]])*(Rebiz!C:C=Table2[[#This Row],[Date]]),Rebiz!E:E,"")} -> 46296.472 | Q12: {=_xlfn.XLOOKUP(1,(Rebiz!A:A=Table2[[#This Row],[Employee]])*(Rebiz!C:C=Table2[[#This Row],[Date]]),Rebiz!F:F,"")} -> 46296.742 | R12: {=_xlfn.XLOOKUP(1,(Rebiz!A:A=Table2[[#This Row],[Employee]])*(Rebiz!C:C=Table2[[#This Row],[Date]]),Rebiz!G:G,"")} -> 6:14 | S12: {=_xlfn.XLOOKUP(1,(Rebiz!A:A=Table2[[#This Row],[Employee]])*(Rebiz!C:C=Table2[[#This Row],[Date]]),Rebiz!H:H,"")} -> 3:5 | T12: {=_xlfn.XLOOKUP(1,(Rebiz!A:A=Table2[[#This Row],[Employee]])*(Rebiz!C:C=Table2[[#This Row],[Date]]),Rebiz!I:I,"")} -> 3:9 | U12: {=_xlfn.XLOOKUP(1,(Rebiz!A:A=Table2[[#This Row],[Employee]])*(Rebiz!C:C=Table2[[#This Row],[Date]]),Rebiz!J:J,"")} -> 0:16 | V12: {=_xlfn.XLOOKUP(1,(Rebiz!A:A=Table2[[#This Row],[Employee]])*(Rebiz!C:C=Table2[[#This Row],[Date]]),Rebiz!K:K,"")} -> Y
A13: Central | B13: DFW North | C13: Stephenville | D13: AUSTIN BROWN | E13: MOBILE ASSOCIATE | F13: 46296 | G13: 0.39583333 | H13: 0.75 | I13: 0.39608796 | J13: 0.75056713 | K13: 7.5 | L13: 7.5172222 | M13: 1 | N13: 59.416667 | O13: On Time | P13: {=_xlfn.XLOOKUP(1,(Rebiz!A:A=Table2[[#This Row],[Employee]])*(Rebiz!C:C=Table2[[#This Row],[Date]]),Rebiz!E:E,"")} -> 46296.397 | Q13: {=_xlfn.XLOOKUP(1,(Rebiz!A:A=Table2[[#This Row],[Employee]])*(Rebiz!C:C=Table2[[#This Row],[Date]]),Rebiz!F:F,"")} -> 46296.757 | R13: {=_xlfn.XLOOKUP(1,(Rebiz!A:A=Table2[[#This Row],[Employee]])*(Rebiz!C:C=Table2[[#This Row],[Date]]),Rebiz!G:G,"")} -> 8:39 | S13: {=_xlfn.XLOOKUP(1,(Rebiz!A:A=Table2[[#This Row],[Employee]])*(Rebiz!C:C=Table2[[#This Row],[Date]]),Rebiz!H:H,"")} -> 7:18 | T13: {=_xlfn.XLOOKUP(1,(Rebiz!A:A=Table2[[#This Row],[Employee]])*(Rebiz!C:C=Table2[[#This Row],[Date]]),Rebiz!I:I,"")} -> 1:21 | U13: {=_xlfn.XLOOKUP(1,(Rebiz!A:A=Table2[[#This Row],[Employee]])*(Rebiz!C:C=Table2[[#This Row],[Date]]),Rebiz!J:J,"")} -> 0:0 | V13: {=_xlfn.XLOOKUP(1,(Rebiz!A:A=Table2[[#This Row],[Employee]])*(Rebiz!C:C=Table2[[#This Row],[Date]]),Rebiz!K:K,"")} -> Y
A14: Central | B14: SA South | C14: Uvalde | D14: MIA LOPEZ | E14: MOBILE ASSOCIATE | F14: 46296 | G14: 0.45833333 | H14: 0.79166667 | I14: 0.46011574 | J14: 0.79436343 | K14: 7 | L14: 6.9305556 | M14: 1 | N14: 65.483333 | O14: On Time | P14: {=_xlfn.XLOOKUP(1,(Rebiz!A:A=Table2[[#This Row],[Employee]])*(Rebiz!C:C=Table2[[#This Row],[Date]]),Rebiz!E:E,"")} -> 46296.464 | Q14: {=_xlfn.XLOOKUP(1,(Rebiz!A:A=Table2[[#This Row],[Employee]])*(Rebiz!C:C=Table2[[#This Row],[Date]]),Rebiz!F:F,"")} -> 46296.797 | R14: {=_xlfn.XLOOKUP(1,(Rebiz!A:A=Table2[[#This Row],[Employee]])*(Rebiz!C:C=Table2[[#This Row],[Date]]),Rebiz!G:G,"")} -> 6:56 | S14: {=_xlfn.XLOOKUP(1,(Rebiz!A:A=Table2[[#This Row],[Employee]])*(Rebiz!C:C=Table2[[#This Row],[Date]]),Rebiz!H:H,"")} -> 6:56 | T14: {=_xlfn.XLOOKUP(1,(Rebiz!A:A=Table2[[#This Row],[Employee]])*(Rebiz!C:C=Table2[[#This Row],[Date]]),Rebiz!I:I,"")} -> 0:0 | U14: {=_xlfn.XLOOKUP(1,(Rebiz!A:A=Table2[[#This Row],[Employee]])*(Rebiz!C:C=Table2[[#This Row],[Date]]),Rebiz!J:J,"")} -> 1:4 | V14: {=_xlfn.XLOOKUP(1,(Rebiz!A:A=Table2[[#This Row],[Employee]])*(Rebiz!C:C=Table2[[#This Row],[Date]]),Rebiz!K:K,"")} -> Y
A15: Central | B15: MO/IA/NE | C15: Hannibal | D15: MARGARET NICHOLLS | E15: MOBILE ASSOCIATE | F15: 46296 | G15: 0.39583333 | H15: 0.75 | K15: 8 | L15: 0 | M15: 0 | N15: 0 | O15: No Show | P15: {=_xlfn.XLOOKUP(1,(Rebiz!A:A=Table2[[#This Row],[Employee]])*(Rebiz!C:C=Table2[[#This Row],[Date]]),Rebiz!E:E,"")} | Q15: {=_xlfn.XLOOKUP(1,(Rebiz!A:A=Table2[[#This Row],[Employee]])*(Rebiz!C:C=Table2[[#This Row],[Date]]),Rebiz!F:F,"")} | R15: {=_xlfn.XLOOKUP(1,(Rebiz!A:A=Table2[[#This Row],[Employee]])*(Rebiz!C:C=Table2[[#This Row],[Date]]),Rebiz!G:G,"")} | S15: {=_xlfn.XLOOKUP(1,(Rebiz!A:A=Table2[[#This Row],[Employee]])*(Rebiz!C:C=Table2[[#This Row],[Date]]),Rebiz!H:H,"")} | T15: {=_xlfn.XLOOKUP(1,(Rebiz!A:A=Table2[[#This Row],[Employee]])*(Rebiz!C:C=Table2[[#This Row],[Date]]),Rebiz!I:I,"")} | U15: {=_xlfn.XLOOKUP(1,(Rebiz!A:A=Table2[[#This Row],[Employee]])*(Rebiz!C:C=Table2[[#This Row],[Date]]),Rebiz!J:J,"")} | V15: {=_xlfn.XLOOKUP(1,(Rebiz!A:A=Table2[[#This Row],[Employee]])*(Rebiz!C:C=Table2[[#This Row],[Date]]),Rebiz!K:K,"")}
A16: Central | B16: SA/Hill Country | C16: Kerrville | D16: JORGE TORRALBA | E16: MOBILE ASSOCIATE | F16: 46296 | G16: 0.39583333 | H16: 0.75 | I16: 0.39353009 | J16: 0.750625 | K16: 7.5 | L16: 7.7313889 | M16: 1 | N16: 50.333333 | O16: On Time | P16: {=_xlfn.XLOOKUP(1,(Rebiz!A:A=Table2[[#This Row],[Employee]])*(Rebiz!C:C=Table2[[#This Row],[Date]]),Rebiz!E:E,"")} | Q16: {=_xlfn.XLOOKUP(1,(Rebiz!A:A=Table2[[#This Row],[Employee]])*(Rebiz!C:C=Table2[[#This Row],[Date]]),Rebiz!F:F,"")} | R16: {=_xlfn.XLOOKUP(1,(Rebiz!A:A=Table2[[#This Row],[Employee]])*(Rebiz!C:C=Table2[[#This Row],[Date]]),Rebiz!G:G,"")} | S16: {=_xlfn.XLOOKUP(1,(Rebiz!A:A=Table2[[#This Row],[Employee]])*(Rebiz!C:C=Table2[[#This Row],[Date]]),Rebiz!H:H,"")} | T16: {=_xlfn.XLOOKUP(1,(Rebiz!A:A=Table2[[#This Row],[Employee]])*(Rebiz!C:C=Table2[[#This Row],[Date]]),Rebiz!I:I,"")} | U16: {=_xlfn.XLOOKUP(1,(Rebiz!A:A=Table2[[#This Row],[Employee]])*(Rebiz!C:C=Table2[[#This Row],[Date]]),Rebiz!J:J,"")} | V16: {=_xlfn.XLOOKUP(1,(Rebiz!A:A=Table2[[#This Row],[Employee]])*(Rebiz!C:C=Table2[[#This Row],[Date]]),Rebiz!K:K,"")}
A17: Central | B17: West Texas | C17: S. Georgia | D17: DELERIA AGUILAR | E17: MOBILE ASSOCIATE | F17: 46296 | G17: 0.54166667 | H17: 0.85416667 | I17: 0.54092593 | J17: 0.85991898 | K17: 7 | L17: 7.1536111 | M17: 1 | N17: 30.133333 | O17: On Time | P17: {=_xlfn.XLOOKUP(1,(Rebiz!A:A=Table2[[#This Row],[Employee]])*(Rebiz!C:C=Table2[[#This Row],[Date]]),Rebiz!E:E,"")} -> 46296.556 | Q17: {=_xlfn.XLOOKUP(1,(Rebiz!A:A=Table2[[#This Row],[Employee]])*(Rebiz!C:C=Table2[[#This Row],[Date]]),Rebiz!F:F,"")} -> 46296.864 | R17: {=_xlfn.XLOOKUP(1,(Rebiz!A:A=Table2[[#This Row],[Employee]])*(Rebiz!C:C=Table2[[#This Row],[Date]]),Rebiz!G:G,"")} -> 6:40 | S17: {=_xlfn.XLOOKUP(1,(Rebiz!A:A=Table2[[#This Row],[Employee]])*(Rebiz!C:C=Table2[[#This Row],[Date]]),Rebiz!H:H,"")} -> 6:40 | T17: {=_xlfn.XLOOKUP(1,(Rebiz!A:A=Table2[[#This Row],[Employee]])*(Rebiz!C:C=Table2[[#This Row],[Date]]),Rebiz!I:I,"")} -> 0:0 | U17: {=_xlfn.XLOOKUP(1,(Rebiz!A:A=Table2[[#This Row],[Employee]])*(Rebiz!C:C=Table2[[#This Row],[Date]]),Rebiz!J:J,"")} -> 0:44 | V17: {=_xlfn.XLOOKUP(1,(Rebiz!A:A=Table2[[#This Row],[Employee]])*(Rebiz!C:C=Table2[[#This Row],[Date]]),Rebiz!K:K,"")} -> Y
A18: Central | B18: South TX/RGV | C18: Viejo | D18: JOSE ROBLES | E18: MOBILE ASSOCIATE | F18: 46296 | G18: 0.47916667 | H18: 0.83333333 | I18: 0.47871528 | J18: 0.87291667 | K18: 8 | L18: 8.6908333 | M18: 1 | N18: 46.2 | O18: Late Clock Out | P18: {=_xlfn.XLOOKUP(1,(Rebiz!A:A=Table2[[#This Row],[Employee]])*(Rebiz!C:C=Table2[[#This Row],[Date]]),Rebiz!E:E,"")} -> 46296.479 | Q18: {=_xlfn.XLOOKUP(1,(Rebiz!A:A=Table2[[#This Row],[Employee]])*(Rebiz!C:C=Table2[[#This Row],[Date]]),Rebiz!F:F,"")} -> 46296.875 | R18: {=_xlfn.XLOOKUP(1,(Rebiz!A:A=Table2[[#This Row],[Employee]])*(Rebiz!C:C=Table2[[#This Row],[Date]]),Rebiz!G:G,"")} -> 9:30 | S18: {=_xlfn.XLOOKUP(1,(Rebiz!A:A=Table2[[#This Row],[Employee]])*(Rebiz!C:C=Table2[[#This Row],[Date]]),Rebiz!H:H,"")} -> 9:30 | T18: {=_xlfn.XLOOKUP(1,(Rebiz!A:A=Table2[[#This Row],[Employee]])*(Rebiz!C:C=Table2[[#This Row],[Date]]),Rebiz!I:I,"")} -> 0:0 | U18: {=_xlfn.XLOOKUP(1,(Rebiz!A:A=Table2[[#This Row],[Employee]])*(Rebiz!C:C=Table2[[#This Row],[Date]]),Rebiz!J:J,"")} -> 0:0 | V18: {=_xlfn.XLOOKUP(1,(Rebiz!A:A=Table2[[#This Row],[Employee]])*(Rebiz!C:C=Table2[[#This Row],[Date]]),Rebiz!K:K,"")} -> Y
A19: Central | B19: DFW North | C19: Weatherford | D19: DARINNAY ALLEN | E19: MOBILE ASSOCIATE | F19: 46296 | G19: 0.375 | H19: 0.66666667 | I19: 0.40760417 | J19: 0.71179398 | K19: 6 | L19: 6.3072222 | M19: 1 | N19: 59.6 | O19: Late Clock Out, Late Clock In | P19: {=_xlfn.XLOOKUP(1,(Rebiz!A:A=Table2[[#This Row],[Employee]])*(Rebiz!C:C=Table2[[#This Row],[Date]]),Rebiz!E:E,"")} -> 46296.409 | Q19: {=_xlfn.XLOOKUP(1,(Rebiz!A:A=Table2[[#This Row],[Employee]])*(Rebiz!C:C=Table2[[#This Row],[Date]]),Rebiz!F:F,"")} -> 46296.713 | R19: {=_xlfn.XLOOKUP(1,(Rebiz!A:A=Table2[[#This Row],[Employee]])*(Rebiz!C:C=Table2[[#This Row],[Date]]),Rebiz!G:G,"")} -> 7:0 | S19: {=_xlfn.XLOOKUP(1,(Rebiz!A:A=Table2[[#This Row],[Employee]])*(Rebiz!C:C=Table2[[#This Row],[Date]]),Rebiz!H:H,"")} -> 5:42 | T19: {=_xlfn.XLOOKUP(1,(Rebiz!A:A=Table2[[#This Row],[Employee]])*(Rebiz!C:C=Table2[[#This Row],[Date]]),Rebiz!I:I,"")} -> 1:18 | U19: {=_xlfn.XLOOKUP(1,(Rebiz!A:A=Table2[[#This Row],[Employee]])*(Rebiz!C:C=Table2[[#This Row],[Date]]),Rebiz!J:J,"")} -> 0:17 | V19: {=_xlfn.XLOOKUP(1,(Rebiz!A:A=Table2[[#This Row],[Employee]])*(Rebiz!C:C=Table2[[#This Row],[Date]]),Rebiz!K:K,"")} -> Y
A20: Central | B20: West Texas | C20: Walmart Court | D20: NYA MARQUEZ | E20: MOBILE ASSOCIATE | F20: 46296 | G20: 0.5 | H20: 0.85416667 | I20: 0.50091435 | J20: 0.86041667 | K20: 8 | L20: 8.1338889 | M20: 1 | N20: 29.65 | O20: On Time | P20: {=_xlfn.XLOOKUP(1,(Rebiz!A:A=Table2[[#This Row],[Employee]])*(Rebiz!C:C=Table2[[#This Row],[Date]]),Rebiz!E:E,"")} -> 46296.503 | Q20: {=_xlfn.XLOOKUP(1,(Rebiz!A:A=Table2[[#This Row],[Employee]])*(Rebiz!C:C=Table2[[#This Row],[Date]]),Rebiz!F:F,"")} -> 46296.863 | R20: {=_xlfn.XLOOKUP(1,(Rebiz!A:A=Table2[[#This Row],[Employee]])*(Rebiz!C:C=Table2[[#This Row],[Date]]),Rebiz!G:G,"")} -> 8:10 | S20: {=_xlfn.XLOOKUP(1,(Rebiz!A:A=Table2[[#This Row],[Employee]])*(Rebiz!C:C=Table2[[#This Row],[Date]]),Rebiz!H:H,"")} -> 4:1 | T20: {=_xlfn.XLOOKUP(1,(Rebiz!A:A=Table2[[#This Row],[Employee]])*(Rebiz!C:C=Table2[[#This Row],[Date]]),Rebiz!I:I,"")} -> 4:9 | U20: {=_xlfn.XLOOKUP(1,(Rebiz!A:A=Table2[[#This Row],[Employee]])*(Rebiz!C:C=Table2[[#This Row],[Date]]),Rebiz!J:J,"")} -> 0:28 | V20: {=_xlfn.XLOOKUP(1,(Rebiz!A:A=Table2[[#This Row],[Employee]])*(Rebiz!C:C=Table2[[#This Row],[Date]]),Rebiz!K:K,"")} -> Y
A21: Central | B21: DFW East | C21: Cooper Street | D21: ABEL HERNANDEZ | E21: MOBILE ASSOCIATE | F21: 46296 | G21: 0.54166667 | H21: 0.89583333 | I21: 0.50607639 | J21: 0.88925926 | K21: 8 | L21: 8.1888889 | M21: 1 | N21: 60.45 | O21: Early Clock In | P21: {=_xlfn.XLOOKUP(1,(Rebiz!A:A=Table2[[#This Row],[Employee]])*(Rebiz!C:C=Table2[[#This Row],[Date]]),Rebiz!E:E,"")} -> 46296.508 | Q21: {=_xlfn.XLOOKUP(1,(Rebiz!A:A=Table2[[#This Row],[Employee]])*(Rebiz!C:C=Table2[[#This Row],[Date]]),Rebiz!F:F,"")} -> 46296.891 | R21: {=_xlfn.XLOOKUP(1,(Rebiz!A:A=Table2[[#This Row],[Employee]])*(Rebiz!C:C=Table2[[#This Row],[Date]]),Rebiz!G:G,"")} -> 9:11 | S21: {=_xlfn.XLOOKUP(1,(Rebiz!A:A=Table2[[#This Row],[Employee]])*(Rebiz!C:C=Table2[[#This Row],[Date]]),Rebiz!H:H,"")} -> 6:41 | T21: {=_xlfn.XLOOKUP(1,(Rebiz!A:A=Table2[[#This Row],[Employee]])*(Rebiz!C:C=Table2[[#This Row],[Date]]),Rebiz!I:I,"")} -> 2:30 | U21: {=_xlfn.XLOOKUP(1,(Rebiz!A:A=Table2[[#This Row],[Employee]])*(Rebiz!C:C=Table2[[#This Row],[Date]]),Rebiz!J:J,"")} -> 0:0 | V21: {=_xlfn.XLOOKUP(1,(Rebiz!A:A=Table2[[#This Row],[Employee]])*(Rebiz!C:C=Table2[[#This Row],[Date]]),Rebiz!K:K,"")} -> Y
A22: Central | B22: Central Texas | C22: Texas Ave | D22: DAMIAN GOMEZ-TORRES | E22: MOBILE ASSOCIATE | F22: 46296 | G22: 0.41666667 | H22: 0.70833333 | I22: 0.41527778 | J22: 0.70940972 | K22: 6 | L22: 6.4425 | M22: 1 | N22: 37 | O22: On Time | P22: {=_xlfn.XLOOKUP(1,(Rebiz!A:A=Table2[[#This Row],[Employee]])*(Rebiz!C:C=Table2[[#This Row],[Date]]),Rebiz!E:E,"")} -> 46296.412 | Q22: {=_xlfn.XLOOKUP(1,(Rebiz!A:A=Table2[[#This Row],[Employee]])*(Rebiz!C:C=Table2[[#This Row],[Date]]),Rebiz!F:F,"")} -> 46296.71 | R22: {=_xlfn.XLOOKUP(1,(Rebiz!A:A=Table2[[#This Row],[Employee]])*(Rebiz!C:C=Table2[[#This Row],[Date]]),Rebiz!G:G,"")} -> 7:10 | S22: {=_xlfn.XLOOKUP(1,(Rebiz!A:A=Table2[[#This Row],[Employee]])*(Rebiz!C:C=Table2[[#This Row],[Date]]),Rebiz!H:H,"")} -> 6:7 | T22: {=_xlfn.XLOOKUP(1,(Rebiz!A:A=Table2[[#This Row],[Employee]])*(Rebiz!C:C=Table2[[#This Row],[Date]]),Rebiz!I:I,"")} -> 1:3 | U22: {=_xlfn.XLOOKUP(1,(Rebiz!A:A=Table2[[#This Row],[Employee]])*(Rebiz!C:C=Table2[[#This Row],[Date]]),Rebiz!J:J,"")} -> 0:0 | V22: {=_xlfn.XLOOKUP(1,(Rebiz!A:A=Table2[[#This Row],[Employee]])*(Rebiz!C:C=Table2[[#This Row],[Date]]),Rebiz!K:K,"")} -> Y
A23: Central | B23: KS/OK | C23: Garth Brooks Blvd | D23: ZACH RHODES | E23: MOBILE ASSOCIATE | F23: 46296 | I23: 0.50168981 | J23: 0.70628472 | K23: 0 | L23: 4.0672222 | M23: 1 | N23: 50.583333 | O23: Not Scheduled | P23: {=_xlfn.XLOOKUP(1,(Rebiz!A:A=Table2[[#This Row],[Employee]])*(Rebiz!C:C=Table2[[#This Row],[Date]]),Rebiz!E:E,"")} -> 46296.499 | Q23: {=_xlfn.XLOOKUP(1,(Rebiz!A:A=Table2[[#This Row],[Employee]])*(Rebiz!C:C=Table2[[#This Row],[Date]]),Rebiz!F:F,"")} -> 46296.709 | R23: {=_xlfn.XLOOKUP(1,(Rebiz!A:A=Table2[[#This Row],[Employee]])*(Rebiz!C:C=Table2[[#This Row],[Date]]),Rebiz!G:G,"")} -> 5:3 | S23: {=_xlfn.XLOOKUP(1,(Rebiz!A:A=Table2[[#This Row],[Employee]])*(Rebiz!C:C=Table2[[#This Row],[Date]]),Rebiz!H:H,"")} -> 5:3 | T23: {=_xlfn.XLOOKUP(1,(Rebiz!A:A=Table2[[#This Row],[Employee]])*(Rebiz!C:C=Table2[[#This Row],[Date]]),Rebiz!I:I,"")} -> 0:0 | U23: {=_xlfn.XLOOKUP(1,(Rebiz!A:A=Table2[[#This Row],[Employee]])*(Rebiz!C:C=Table2[[#This Row],[Date]]),Rebiz!J:J,"")} -> 0:0 | V23: {=_xlfn.XLOOKUP(1,(Rebiz!A:A=Table2[[#This Row],[Employee]])*(Rebiz!C:C=Table2[[#This Row],[Date]]),Rebiz!K:K,"")} -> Y
A24: Central | B24: SA/Hill Country | C24: Creekside | D24: ASA LEE | E24: MOBILE ASSOCIATE | F24: 46296 | G24: 0.39583333 | H24: 0.70833333 | I24: 0.39309028 | J24: 0.71862269 | K24: 6.5 | L24: 6.9186111 | M24: 1 | N24: 53.65 | O24: On Time | P24: {=_xlfn.XLOOKUP(1,(Rebiz!A:A=Table2[[#This Row],[Employee]])*(Rebiz!C:C=Table2[[#This Row],[Date]]),Rebiz!E:E,"")} | Q24: {=_xlfn.XLOOKUP(1,(Rebiz!A:A=Table2[[#This Row],[Employee]])*(Rebiz!C:C=Table2[[#This Row],[Date]]),Rebiz!F:F,"")} | R24: {=_xlfn.XLOOKUP(1,(Rebiz!A:A=Table2[[#This Row],[Employee]])*(Rebiz!C:C=Table2[[#This Row],[Date]]),Rebiz!G:G,"")} | S24: {=_xlfn.XLOOKUP(1,(Rebiz!A:A=Table2[[#This Row],[Employee]])*(Rebiz!C:C=Table2[[#This Row],[Date]]),Rebiz!H:H,"")} | T24: {=_xlfn.XLOOKUP(1,(Rebiz!A:A=Table2[[#This Row],[Employee]])*(Rebiz!C:C=Table2[[#This Row],[Date]]),Rebiz!I:I,"")} | U24: {=_xlfn.XLOOKUP(1,(Rebiz!A:A=Table2[[#This Row],[Employee]])*(Rebiz!C:C=Table2[[#This Row],[Date]]),Rebiz!J:J,"")} | V24: {=_xlfn.XLOOKUP(1,(Rebiz!A:A=Table2[[#This Row],[Employee]])*(Rebiz!C:C=Table2[[#This Row],[Date]]),Rebiz!K:K,"")}
A25: Central | B25: DFW North | C25: Stephenville | D25: GABRIELLA LIENDO BARRON | E25: MOBILE ASSOCIATE | F25: 46296 | G25: 0.54166667 | H25: 0.85416667 | I25: 0.54240741 | J25: 0.84076389 | K25: 6.5 | L25: 6.1522222 | M25: 1 | N25: 60.5 | O25: Early Clock Out | P25: {=_xlfn.XLOOKUP(1,(Rebiz!A:A=Table2[[#This Row],[Employee]])*(Rebiz!C:C=Table2[[#This Row],[Date]]),Rebiz!E:E,"")} -> 46296.549 | Q25: {=_xlfn.XLOOKUP(1,(Rebiz!A:A=Table2[[#This Row],[Employee]])*(Rebiz!C:C=Table2[[#This Row],[Date]]),Rebiz!F:F,"")} -> 46296.844 | R25: {=_xlfn.XLOOKUP(1,(Rebiz!A:A=Table2[[#This Row],[Employee]])*(Rebiz!C:C=Table2[[#This Row],[Date]]),Rebiz!G:G,"")} -> 6:4 | S25: {=_xlfn.XLOOKUP(1,(Rebiz!A:A=Table2[[#This Row],[Employee]])*(Rebiz!C:C=Table2[[#This Row],[Date]]),Rebiz!H:H,"")} -> 5:55 | T25: {=_xlfn.XLOOKUP(1,(Rebiz!A:A=Table2[[#This Row],[Employee]])*(Rebiz!C:C=Table2[[#This Row],[Date]]),Rebiz!I:I,"")} -> 0:9 | U25: {=_xlfn.XLOOKUP(1,(Rebiz!A:A=Table2[[#This Row],[Employee]])*(Rebiz!C:C=Table2[[#This Row],[Date]]),Rebiz!J:J,"")} -> 1:1 | V25: {=_xlfn.XLOOKUP(1,(Rebiz!A:A=Table2[[#This Row],[Employee]])*(Rebiz!C:C=Table2[[#This Row],[Date]]),Rebiz!K:K,"")} -> Y
A26: Central | B26: DFW East | C26: Walnut | D26: BRANDON LOPEZ-RODRIGUEZ | E26: MOBILE ASSOCIATE | F26: 46296 | G26: 0.45833333 | H26: 0.83333333 | I26: 0.45733796 | J26: 0.84027778 | K26: 8 | L26: 8.2008333 | M26: 1 | N26: 59.383333 | O26: On Time | P26: {=_xlfn.XLOOKUP(1,(Rebiz!A:A=Table2[[#This Row],[Employee]])*(Rebiz!C:C=Table2[[#This Row],[Date]]),Rebiz!E:E,"")} -> 46296.46 | Q26: {=_xlfn.XLOOKUP(1,(Rebiz!A:A=Table2[[#This Row],[Employee]])*(Rebiz!C:C=Table2[[#This Row],[Date]]),Rebiz!F:F,"")} -> 46296.849 | R26: {=_xlfn.XLOOKUP(1,(Rebiz!A:A=Table2[[#This Row],[Employee]])*(Rebiz!C:C=Table2[[#This Row],[Date]]),Rebiz!G:G,"")} -> 9:20 | S26: {=_xlfn.XLOOKUP(1,(Rebiz!A:A=Table2[[#This Row],[Employee]])*(Rebiz!C:C=Table2[[#This Row],[Date]]),Rebiz!H:H,"")} -> 9:20 | T26: {=_xlfn.XLOOKUP(1,(Rebiz!A:A=Table2[[#This Row],[Employee]])*(Rebiz!C:C=Table2[[#This Row],[Date]]),Rebiz!I:I,"")} -> 0:0 | U26: {=_xlfn.XLOOKUP(1,(Rebiz!A:A=Table2[[#This Row],[Employee]])*(Rebiz!C:C=Table2[[#This Row],[Date]]),Rebiz!J:J,"")} -> 0:0 | V26: {=_xlfn.XLOOKUP(1,(Rebiz!A:A=Table2[[#This Row],[Employee]])*(Rebiz!C:C=Table2[[#This Row],[Date]]),Rebiz!K:K,"")} -> Y
A27: Central | B27: MO/IA/NE | C27: Rolla | D27: PRESTON MELTON | E27: MOBILE ASSOCIATE | F27: 46296 | G27: 0.375 | H27: 0.70833333 | I27: 0.3740625 | J27: 0.7162963 | K27: 7.5 | L27: 7.7069444 | M27: 1 | N27: 30.4 | O27: On Time | P27: {=_xlfn.XLOOKUP(1,(Rebiz!A:A=Table2[[#This Row],[Employee]])*(Rebiz!C:C=Table2[[#This Row],[Date]]),Rebiz!E:E,"")} -> 46296.376 | Q27: {=_xlfn.XLOOKUP(1,(Rebiz!A:A=Table2[[#This Row],[Employee]])*(Rebiz!C:C=Table2[[#This Row],[Date]]),Rebiz!F:F,"")} -> 46296.717 | R27: {=_xlfn.XLOOKUP(1,(Rebiz!A:A=Table2[[#This Row],[Employee]])*(Rebiz!C:C=Table2[[#This Row],[Date]]),Rebiz!G:G,"")} -> 7:22 | S27: {=_xlfn.XLOOKUP(1,(Rebiz!A:A=Table2[[#This Row],[Employee]])*(Rebiz!C:C=Table2[[#This Row],[Date]]),Rebiz!H:H,"")} -> 7:22 | T27: {=_xlfn.XLOOKUP(1,(Rebiz!A:A=Table2[[#This Row],[Employee]])*(Rebiz!C:C=Table2[[#This Row],[Date]]),Rebiz!I:I,"")} -> 0:0 | U27: {=_xlfn.XLOOKUP(1,(Rebiz!A:A=Table2[[#This Row],[Employee]])*(Rebiz!C:C=Table2[[#This Row],[Date]]),Rebiz!J:J,"")} -> 0:49 | V27: {=_xlfn.XLOOKUP(1,(Rebiz!A:A=Table2[[#This Row],[Employee]])*(Rebiz!C:C=Table2[[#This Row],[Date]]),Rebiz!K:K,"")} -> Y
A28: Central | B28: MO/IA/NE | C28: Grand Island | D28: DAMARIS MEIGHAN | E28: MOBILE ASSOCIATE | F28: 46296 | G28: 0.39583333 | H28: 0.75 | I28: 0.39614583 | J28: 0.70887731 | K28: 8 | L28: 6.6805556 | M28: 1 | N28: 49.5 | O28: Early Clock Out | P28: {=_xlfn.XLOOKUP(1,(Rebiz!A:A=Table2[[#This Row],[Employee]])*(Rebiz!C:C=Table2[[#This Row],[Date]]),Rebiz!E:E,"")} -> 46296.397 | Q28: {=_xlfn.XLOOKUP(1,(Rebiz!A:A=Table2[[#This Row],[Employee]])*(Rebiz!C:C=Table2[[#This Row],[Date]]),Rebiz!F:F,"")} -> 46296.711 | R28: {=_xlfn.XLOOKUP(1,(Rebiz!A:A=Table2[[#This Row],[Employee]])*(Rebiz!C:C=Table2[[#This Row],[Date]]),Rebiz!G:G,"")} -> 6:45 | S28: {=_xlfn.XLOOKUP(1,(Rebiz!A:A=Table2[[#This Row],[Employee]])*(Rebiz!C:C=Table2[[#This Row],[Date]]),Rebiz!H:H,"")} -> 6:39 | T28: {=_xlfn.XLOOKUP(1,(Rebiz!A:A=Table2[[#This Row],[Employee]])*(Rebiz!C:C=Table2[[#This Row],[Date]]),Rebiz!I:I,"")} -> 0:6 | U28: {=_xlfn.XLOOKUP(1,(Rebiz!A:A=Table2[[#This Row],[Employee]])*(Rebiz!C:C=Table2[[#This Row],[Date]]),Rebiz!J:J,"")} -> 0:48 | V28: {=_xlfn.XLOOKUP(1,(Rebiz!A:A=Table2[[#This Row],[Employee]])*(Rebiz!C:C=Table2[[#This Row],[Date]]),Rebiz!K:K,"")} -> Y
A29: Central | B29: DFW East | C29: Pines Road | D29: BRIANNA GLOVER | E29: MOBILE ASSOCIATE | F29: 46296 | G29: 0.5 | H29: 0.79166667 | K29: 6.5 | L29: 0 | M29: 0 | N29: 0 | O29: No Show | P29: {=_xlfn.XLOOKUP(1,(Rebiz!A:A=Table2[[#This Row],[Employee]])*(Rebiz!C:C=Table2[[#This Row],[Date]]),Rebiz!E:E,"")} | Q29: {=_xlfn.XLOOKUP(1,(Rebiz!A:A=Table2[[#This Row],[Employee]])*(Rebiz!C:C=Table2[[#This Row],[Date]]),Rebiz!F:F,"")} | R29: {=_xlfn.XLOOKUP(1,(Rebiz!A:A=Table2[[#This Row],[Employee]])*(Rebiz!C:C=Table2[[#This Row],[Date]]),Rebiz!G:G,"")} | S29: {=_xlfn.XLOOKUP(1,(Rebiz!A:A=Table2[[#This Row],[Employee]])*(Rebiz!C:C=Table2[[#This Row],[Date]]),Rebiz!H:H,"")} | T29: {=_xlfn.XLOOKUP(1,(Rebiz!A:A=Table2[[#This Row],[Employee]])*(Rebiz!C:C=Table2[[#This Row],[Date]]),Rebiz!I:I,"")} | U29: {=_xlfn.XLOOKUP(1,(Rebiz!A:A=Table2[[#This Row],[Employee]])*(Rebiz!C:C=Table2[[#This Row],[Date]]),Rebiz!J:J,"")} | V29: {=_xlfn.XLOOKUP(1,(Rebiz!A:A=Table2[[#This Row],[Employee]])*(Rebiz!C:C=Table2[[#This Row],[Date]]),Rebiz!K:K,"")}
A30: Central | B30: DFW East | C30: Eastchase | D30: ANGEL RUBALCAVA | E30: MOBILE ASSOCIATE | F30: 46296 | G30: 0.45833333 | H30: 0.85416667 | I30: 0.43159722 | J30: 0.79372685 | K30: 8.5 | L30: 7.7180556 | M30: 1 | N30: 58.383333 | O30: Early Clock In, Early Clock Out | P30: {=_xlfn.XLOOKUP(1,(Rebiz!A:A=Table2[[#This Row],[Employee]])*(Rebiz!C:C=Table2[[#This Row],[Date]]),Rebiz!E:E,"")} -> 46296.432 | Q30: {=_xlfn.XLOOKUP(1,(Rebiz!A:A=Table2[[#This Row],[Employee]])*(Rebiz!C:C=Table2[[#This Row],[Date]]),Rebiz!F:F,"")} -> 46296.797 | R30: {=_xlfn.XLOOKUP(1,(Rebiz!A:A=Table2[[#This Row],[Employee]])*(Rebiz!C:C=Table2[[#This Row],[Date]]),Rebiz!G:G,"")} -> 8:30 | S30: {=_xlfn.XLOOKUP(1,(Rebiz!A:A=Table2[[#This Row],[Employee]])*(Rebiz!C:C=Table2[[#This Row],[Date]]),Rebiz!H:H,"")} -> 7:18 | T30: {=_xlfn.XLOOKUP(1,(Rebiz!A:A=Table2[[#This Row],[Employee]])*(Rebiz!C:C=Table2[[#This Row],[Date]]),Rebiz!I:I,"")} -> 1:12 | U30: {=_xlfn.XLOOKUP(1,(Rebiz!A:A=Table2[[#This Row],[Employee]])*(Rebiz!C:C=Table2[[#This Row],[Date]]),Rebiz!J:J,"")} -> 0:16 | V30: {=_xlfn.XLOOKUP(1,(Rebiz!A:A=Table2[[#This Row],[Employee]])*(Rebiz!C:C=Table2[[#This Row],[Date]]),Rebiz!K:K,"")} -> Y
A31: Central | B31: Central Texas | C31: Marble Falls | D31: ALEX TURLEY | E31: MOBILE ASSOCIATE | F31: 46296 | G31: 0.5 | H31: 0.84375 | I31: 0.50005787 | J31: 0.84892361 | K31: 7.75 | L31: 7.8147222 | M31: 1 | N31: 33.483333 | O31: On Time | P31: {=_xlfn.XLOOKUP(1,(Rebiz!A:A=Table2[[#This Row],[Employee]])*(Rebiz!C:C=Table2[[#This Row],[Date]]),Rebiz!E:E,"")} -> 46296.499 | Q31: {=_xlfn.XLOOKUP(1,(Rebiz!A:A=Table2[[#This Row],[Employee]])*(Rebiz!C:C=Table2[[#This Row],[Date]]),Rebiz!F:F,"")} -> 46296.851 | R31: {=_xlfn.XLOOKUP(1,(Rebiz!A:A=Table2[[#This Row],[Employee]])*(Rebiz!C:C=Table2[[#This Row],[Date]]),Rebiz!G:G,"")} -> 8:14 | S31: {=_xlfn.XLOOKUP(1,(Rebiz!A:A=Table2[[#This Row],[Employee]])*(Rebiz!C:C=Table2[[#This Row],[Date]]),Rebiz!H:H,"")} -> 7:23 | T31: {=_xlfn.XLOOKUP(1,(Rebiz!A:A=Table2[[#This Row],[Employee]])*(Rebiz!C:C=Table2[[#This Row],[Date]]),Rebiz!I:I,"")} -> 0:51 | U31: {=_xlfn.XLOOKUP(1,(Rebiz!A:A=Table2[[#This Row],[Employee]])*(Rebiz!C:C=Table2[[#This Row],[Date]]),Rebiz!J:J,"")} -> 0:13 | V31: {=_xlfn.XLOOKUP(1,(Rebiz!A:A=Table2[[#This Row],[Employee]])*(Rebiz!C:C=Table2[[#This Row],[Date]]),Rebiz!K:K,"")} -> Y
A32: Central | B32: South TX/RGV | C32: Ocean Blvd | D32: ALEJANDRA SILGUERO | E32: MOBILE ASSOCIATE | F32: 46296 | G32: 0.5 | H32: 0.85416667 | I32: 0.50027778 | J32: 0.85141204 | K32: 8 | L32: 7.5755556 | M32: 1 | N32: 51.1 | O32: On Time | P32: {=_xlfn.XLOOKUP(1,(Rebiz!A:A=Table2[[#This Row],[Employee]])*(Rebiz!C:C=Table2[[#This Row],[Date]]),Rebiz!E:E,"")} | Q32: {=_xlfn.XLOOKUP(1,(Rebiz!A:A=Table2[[#This Row],[Employee]])*(Rebiz!C:C=Table2[[#This Row],[Date]]),Rebiz!F:F,"")} | R32: {=_xlfn.XLOOKUP(1,(Rebiz!A:A=Table2[[#This Row],[Employee]])*(Rebiz!C:C=Table2[[#This Row],[Date]]),Rebiz!G:G,"")} | S32: {=_xlfn.XLOOKUP(1,(Rebiz!A:A=Table2[[#This Row],[Employee]])*(Rebiz!C:C=Table2[[#This Row],[Date]]),Rebiz!H:H,"")} | T32: {=_xlfn.XLOOKUP(1,(Rebiz!A:A=Table2[[#This Row],[Employee]])*(Rebiz!C:C=Table2[[#This Row],[Date]]),Rebiz!I:I,"")} | U32: {=_xlfn.XLOOKUP(1,(Rebiz!A:A=Table2[[#This Row],[Employee]])*(Rebiz!C:C=Table2[[#This Row],[Date]]),Rebiz!J:J,"")} | V32: {=_xlfn.XLOOKUP(1,(Rebiz!A:A=Table2[[#This Row],[Employee]])*(Rebiz!C:C=Table2[[#This Row],[Date]]),Rebiz!K:K,"")}
A33: Central | B33: KS/OK | C33: Schilling | D33: KYLE BURCH | E33: MOBILE ASSOCIATE | F33: 46296 | I33: 0.45277778 | J33: 0.71738426 | K33: 0 | L33: 5.8505556 | M33: 1 | N33: 30 | O33: Not Scheduled | P33: {=_xlfn.XLOOKUP(1,(Rebiz!A:A=Table2[[#This Row],[Employee]])*(Rebiz!C:C=Table2[[#This Row],[Date]]),Rebiz!E:E,"")} -> 46296.456 | Q33: {=_xlfn.XLOOKUP(1,(Rebiz!A:A=Table2[[#This Row],[Employee]])*(Rebiz!C:C=Table2[[#This Row],[Date]]),Rebiz!F:F,"")} -> 46296.721 | R33: {=_xlfn.XLOOKUP(1,(Rebiz!A:A=Table2[[#This Row],[Employee]])*(Rebiz!C:C=Table2[[#This Row],[Date]]),Rebiz!G:G,"")} -> 6:22 | S33: {=_xlfn.XLOOKUP(1,(Rebiz!A:A=Table2[[#This Row],[Employee]])*(Rebiz!C:C=Table2[[#This Row],[Date]]),Rebiz!H:H,"")} -> 3:22 | T33: {=_xlfn.XLOOKUP(1,(Rebiz!A:A=Table2[[#This Row],[Employee]])*(Rebiz!C:C=Table2[[#This Row],[Date]]),Rebiz!I:I,"")} -> 3:0 | U33: {=_xlfn.XLOOKUP(1,(Rebiz!A:A=Table2[[#This Row],[Employee]])*(Rebiz!C:C=Table2[[#This Row],[Date]]),Rebiz!J:J,"")} -> 0:0 | V33: {=_xlfn.XLOOKUP(1,(Rebiz!A:A=Table2[[#This Row],[Employee]])*(Rebiz!C:C=Table2[[#This Row],[Date]]),Rebiz!K:K,"")} -> Y
A34: Central | B34: KS/OK | C34: Ardmore | D34: MICHAEL RODRIGUEZ | E34: MOBILE ASSOCIATE | F34: 46296 | G34: 0.5 | H34: 0.83333333 | I34: 0.50353009 | J34: 0.8505787 | K34: 7 | L34: 7.8361111 | M34: 1 | N34: 29.583333 | O34: Late Clock Out | P34: {=_xlfn.XLOOKUP(1,(Rebiz!A:A=Table2[[#This Row],[Employee]])*(Rebiz!C:C=Table2[[#This Row],[Date]]),Rebiz!E:E,"")} | Q34: {=_xlfn.XLOOKUP(1,(Rebiz!A:A=Table2[[#This Row],[Employee]])*(Rebiz!C:C=Table2[[#This Row],[Date]]),Rebiz!F:F,"")} | R34: {=_xlfn.XLOOKUP(1,(Rebiz!A:A=Table2[[#This Row],[Employee]])*(Rebiz!C:C=Table2[[#This Row],[Date]]),Rebiz!G:G,"")} | S34: {=_xlfn.XLOOKUP(1,(Rebiz!A:A=Table2[[#This Row],[Employee]])*(Rebiz!C:C=Table2[[#This Row],[Date]]),Rebiz!H:H,"")} | T34: {=_xlfn.XLOOKUP(1,(Rebiz!A:A=Table2[[#This Row],[Employee]])*(Rebiz!C:C=Table2[[#This Row],[Date]]),Rebiz!I:I,"")} | U34: {=_xlfn.XLOOKUP(1,(Rebiz!A:A=Table2[[#This Row],[Employee]])*(Rebiz!C:C=Table2[[#This Row],[Date]]),Rebiz!J:J,"")} | V34: {=_xlfn.XLOOKUP(1,(Rebiz!A:A=Table2[[#This Row],[Employee]])*(Rebiz!C:C=Table2[[#This Row],[Date]]),Rebiz!K:K,"")}
A35: Central | B35: KS/OK | C35: Owen Garriott | D35: KEVIN DE LA TORRE | E35: MOBILE ASSOCIATE | F35: 46296 | G35: 0.45833333 | H35: 0.75 | I35: 0.45747685 | J35: 0.74844907 | K35: 6.5 | L35: 6.475 | M35: 1 | N35: 30.5 | O35: On Time | P35: {=_xlfn.XLOOKUP(1,(Rebiz!A:A=Table2[[#This Row],[Employee]])*(Rebiz!C:C=Table2[[#This Row],[Date]]),Rebiz!E:E,"")} -> 46296.46 | Q35: {=_xlfn.XLOOKUP(1,(Rebiz!A:A=Table2[[#This Row],[Employee]])*(Rebiz!C:C=Table2[[#This Row],[Date]]),Rebiz!F:F,"")} -> 46296.75 | R35: {=_xlfn.XLOOKUP(1,(Rebiz!A:A=Table2[[#This Row],[Employee]])*(Rebiz!C:C=Table2[[#This Row],[Date]]),Rebiz!G:G,"")} -> 6:28 | S35: {=_xlfn.XLOOKUP(1,(Rebiz!A:A=Table2[[#This Row],[Employee]])*(Rebiz!C:C=Table2[[#This Row],[Date]]),Rebiz!H:H,"")} -> 6:22 | T35: {=_xlfn.XLOOKUP(1,(Rebiz!A:A=Table2[[#This Row],[Employee]])*(Rebiz!C:C=Table2[[#This Row],[Date]]),Rebiz!I:I,"")} -> 0:6 | U35: {=_xlfn.XLOOKUP(1,(Rebiz!A:A=Table2[[#This Row],[Employee]])*(Rebiz!C:C=Table2[[#This Row],[Date]]),Rebiz!J:J,"")} -> 0:30 | V35: {=_xlfn.XLOOKUP(1,(Rebiz!A:A=Table2[[#This Row],[Employee]])*(Rebiz!C:C=Table2[[#This Row],[Date]]),Rebiz!K:K,"")} -> Y
A36: Central | B36: South TX/RGV | C36: Rockport | D36: AVERY STRUBE | E36: MOBILE ASSOCIATE | F36: 46296 | G36: 0.5 | H36: 0.75 | I36: 0.50003472 | J36: 0.77710648 | K36: 5.5 | L36: 6.1461111 | M36: 1 | N36: 30.216667 | O36: Late Clock Out | P36: {=_xlfn.XLOOKUP(1,(Rebiz!A:A=Table2[[#This Row],[Employee]])*(Rebiz!C:C=Table2[[#This Row],[Date]]),Rebiz!E:E,"")} -> 46296.5 | Q36: {=_xlfn.XLOOKUP(1,(Rebiz!A:A=Table2[[#This Row],[Employee]])*(Rebiz!C:C=Table2[[#This Row],[Date]]),Rebiz!F:F,"")} -> 46296.781 | R36: {=_xlfn.XLOOKUP(1,(Rebiz!A:A=Table2[[#This Row],[Employee]])*(Rebiz!C:C=Table2[[#This Row],[Date]]),Rebiz!G:G,"")} -> 6:22 | S36: {=_xlfn.XLOOKUP(1,(Rebiz!A:A=Table2[[#This Row],[Employee]])*(Rebiz!C:C=Table2[[#This Row],[Date]]),Rebiz!H:H,"")} -> 6:4 | T36: {=_xlfn.XLOOKUP(1,(Rebiz!A:A=Table2[[#This Row],[Employee]])*(Rebiz!C:C=Table2[[#This Row],[Date]]),Rebiz!I:I,"")} -> 0:18 | U36: {=_xlfn.XLOOKUP(1,(Rebiz!A:A=Table2[[#This Row],[Employee]])*(Rebiz!C:C=Table2[[#This Row],[Date]]),Rebiz!J:J,"")} -> 0:22 | V36: {=_xlfn.XLOOKUP(1,(Rebiz!A:A=Table2[[#This Row],[Employee]])*(Rebiz!C:C=Table2[[#This Row],[Date]]),Rebiz!K:K,"")} -> Y
A37: Central | B37: DFW North | C37: Granbury | D37: JONATHAN LOPEZ | E37: MOBILE ASSOCIATE | F37: 46296 | G37: 0.47916667 | H37: 0.85416667 | I37: 0.45244213 | J37: 0.83626157 | K37: 8 | L37: 8.1291667 | M37: 1 | N37: 64.95 | O37: Early Clock In, Early Clock Out | P37: {=_xlfn.XLOOKUP(1,(Rebiz!A:A=Table2[[#This Row],[Employee]])*(Rebiz!C:C=Table2[[#This Row],[Date]]),Rebiz!E:E,"")} -> 46296.454 | Q37: {=_xlfn.XLOOKUP(1,(Rebiz!A:A=Table2[[#This Row],[Employee]])*(Rebiz!C:C=Table2[[#This Row],[Date]]),Rebiz!F:F,"")} -> 46296.839 | R37: {=_xlfn.XLOOKUP(1,(Rebiz!A:A=Table2[[#This Row],[Employee]])*(Rebiz!C:C=Table2[[#This Row],[Date]]),Rebiz!G:G,"")} -> 8:6 | S37: {=_xlfn.XLOOKUP(1,(Rebiz!A:A=Table2[[#This Row],[Employee]])*(Rebiz!C:C=Table2[[#This Row],[Date]]),Rebiz!H:H,"")} -> 7:21 | T37: {=_xlfn.XLOOKUP(1,(Rebiz!A:A=Table2[[#This Row],[Employee]])*(Rebiz!C:C=Table2[[#This Row],[Date]]),Rebiz!I:I,"")} -> 0:45 | U37: {=_xlfn.XLOOKUP(1,(Rebiz!A:A=Table2[[#This Row],[Employee]])*(Rebiz!C:C=Table2[[#This Row],[Date]]),Rebiz!J:J,"")} -> 1:8 | V37: {=_xlfn.XLOOKUP(1,(Rebiz!A:A=Table2[[#This Row],[Employee]])*(Rebiz!C:C=Table2[[#This Row],[Date]]),Rebiz!K:K,"")} -> Y
A38: Central | B38: MO/IA/NE | C38: Hannibal | D38: XANDER MARTIN | E38: MOBILE ASSOCIATE | F38: 46296 | G38: 0.5 | H38: 0.85416667 | K38: 8 | L38: 0 | M38: 0 | N38: 0 | O38: No Show | P38: {=_xlfn.XLOOKUP(1,(Rebiz!A:A=Table2[[#This Row],[Employee]])*(Rebiz!C:C=Table2[[#This Row],[Date]]),Rebiz!E:E,"")} | Q38: {=_xlfn.XLOOKUP(1,(Rebiz!A:A=Table2[[#This Row],[Employee]])*(Rebiz!C:C=Table2[[#This Row],[Date]]),Rebiz!F:F,"")} | R38: {=_xlfn.XLOOKUP(1,(Rebiz!A:A=Table2[[#This Row],[Employee]])*(Rebiz!C:C=Table2[[#This Row],[Date]]),Rebiz!G:G,"")} | S38: {=_xlfn.XLOOKUP(1,(Rebiz!A:A=Table2[[#This Row],[Employee]])*(Rebiz!C:C=Table2[[#This Row],[Date]]),Rebiz!H:H,"")} | T38: {=_xlfn.XLOOKUP(1,(Rebiz!A:A=Table2[[#This Row],[Employee]])*(Rebiz!C:C=Table2[[#This Row],[Date]]),Rebiz!I:I,"")} | U38: {=_xlfn.XLOOKUP(1,(Rebiz!A:A=Table2[[#This Row],[Employee]])*(Rebiz!C:C=Table2[[#This Row],[Date]]),Rebiz!J:J,"")} | V38: {=_xlfn.XLOOKUP(1,(Rebiz!A:A=Table2[[#This Row],[Employee]])*(Rebiz!C:C=Table2[[#This Row],[Date]]),Rebiz!K:K,"")}
A39: Central | B39: MO/IA/NE | C39: Center | D39: CLAUDETTE DENNIS | E39: MOBILE ASSOCIATE | F39: 46296 | G39: 0.39583333 | H39: 0.83333333 | I39: 0.39814815 | J39: 0.8371875 | K39: 10 | L39: 10.042222 | M39: 1 | N39: 29.683333 | O39: On Time | P39: {=_xlfn.XLOOKUP(1,(Rebiz!A:A=Table2[[#This Row],[Employee]])*(Rebiz!C:C=Table2[[#This Row],[Date]]),Rebiz!E:E,"")} -> 46296.399 | Q39: {=_xlfn.XLOOKUP(1,(Rebiz!A:A=Table2[[#This Row],[Employee]])*(Rebiz!C:C=Table2[[#This Row],[Date]]),Rebiz!F:F,"")} -> 46296.843 | R39: {=_xlfn.XLOOKUP(1,(Rebiz!A:A=Table2[[#This Row],[Employee]])*(Rebiz!C:C=Table2[[#This Row],[Date]]),Rebiz!G:G,"")} -> 10:40 | S39: {=_xlfn.XLOOKUP(1,(Rebiz!A:A=Table2[[#This Row],[Employee]])*(Rebiz!C:C=Table2[[#This Row],[Date]]),Rebiz!H:H,"")} -> 10:40 | T39: {=_xlfn.XLOOKUP(1,(Rebiz!A:A=Table2[[#This Row],[Employee]])*(Rebiz!C:C=Table2[[#This Row],[Date]]),Rebiz!I:I,"")} -> 0:0 | U39: {=_xlfn.XLOOKUP(1,(Rebiz!A:A=Table2[[#This Row],[Employee]])*(Rebiz!C:C=Table2[[#This Row],[Date]]),Rebiz!J:J,"")} -> 0:0 | V39: {=_xlfn.XLOOKUP(1,(Rebiz!A:A=Table2[[#This Row],[Employee]])*(Rebiz!C:C=Table2[[#This Row],[Date]]),Rebiz!K:K,"")} -> Y
A40: Central | B40: MO/IA/NE | C40: King Lane | D40: JEFFREY SURA | E40: MOBILE ASSOCIATE | F40: 46296 | G40: 0.375 | H40: 0.70833333 | I40: 0.38459491 | J40: 0.72356481 | K40: 7.5 | L40: 7.5933333 | M40: 1 | N40: 32.516667 | O40: Late Clock Out, Late Clock In | P40: {=_xlfn.XLOOKUP(1,(Rebiz!A:A=Table2[[#This Row],[Employee]])*(Rebiz!C:C=Table2[[#This Row],[Date]]),Rebiz!E:E,"")} -> 46296.387 | Q40: {=_xlfn.XLOOKUP(1,(Rebiz!A:A=Table2[[#This Row],[Employee]])*(Rebiz!C:C=Table2[[#This Row],[Date]]),Rebiz!F:F,"")} -> 46296.726 | R40: {=_xlfn.XLOOKUP(1,(Rebiz!A:A=Table2[[#This Row],[Employee]])*(Rebiz!C:C=Table2[[#This Row],[Date]]),Rebiz!G:G,"")} -> 8:8 | S40: {=_xlfn.XLOOKUP(1,(Rebiz!A:A=Table2[[#This Row],[Employee]])*(Rebiz!C:C=Table2[[#This Row],[Date]]),Rebiz!H:H,"")} -> 5:23 | T40: {=_xlfn.XLOOKUP(1,(Rebiz!A:A=Table2[[#This Row],[Employee]])*(Rebiz!C:C=Table2[[#This Row],[Date]]),Rebiz!I:I,"")} -> 2:45 | U40: {=_xlfn.XLOOKUP(1,(Rebiz!A:A=Table2[[#This Row],[Employee]])*(Rebiz!C:C=Table2[[#This Row],[Date]]),Rebiz!J:J,"")} -> 0:0 | V40: {=_xlfn.XLOOKUP(1,(Rebiz!A:A=Table2[[#This Row],[Employee]])*(Rebiz!C:C=Table2[[#This Row],[Date]]),Rebiz!K:K,"")} -> Y
...

Sheet Rebiz
A1: Employee | B1: Location | C1: Date | D1: Employee2 | E1: Camera In | F1: Camera Out | G1: Total Time | H1: Showroom Time | I1: Backroom Time | J1: Break | K1: Monitored
A2: =TRIM(_xlfn.TEXTBEFORE(D2,"(")) -> DANA GLASS | B2: 2VSY: Springboro | C2: 46296 | D2: DANA GLASS (112301) | E2: 46296.6 | F2: 46296.759 | G2: 3:25 | H2: 3:25 | I2: 0:0 | J2: 0:24 | K2: Y
A3: =TRIM(_xlfn.TEXTBEFORE(D3,"(")) -> JORDAN REED | B3: 2VSY: Springboro | C3: 46296 | D3: JORDAN REED (125037) | E3: 46296.399 | F3: 46296.863 | G3: 10:31 | H3: 9:43 | I3: 0:48 | J3: 0:38 | K3: Y
A4: =TRIM(_xlfn.TEXTBEFORE(D4,"(")) -> WENDY ADAMS | B4: 2WSL: Springfield | C4: 46296 | D4: WENDY ADAMS (110752) | E4: 46296.376 | F4: 46296.754 | G4: 8:45 | H4: 6:54 | I4: 1:51 | J4: 0:19 | K4: Y
A5: =TRIM(_xlfn.TEXTBEFORE(D5,"(")) -> ADAM SEVERS | B5: 2WSL: Springfield | C5: 46296 | D5: ADAM SEVERS (124383) | E5: 46296.458 | F5: 46296.849 | G5: 8:51 | H5: 8:18 | I5: 0:33 | J5: 0:32 | K5: Y
A6: =TRIM(_xlfn.TEXTBEFORE(D6,"(")) -> LUIS CORONA | B6: 2WSL: Springfield | C6: 46296 | D6: LUIS CORONA (110427) | E6: 1 | F6: 1 | G6: 0:0 | H6: 0:0 | I6: 0:0 | J6: 0:0 | K6: Y
A7: =TRIM(_xlfn.TEXTBEFORE(D7,"(")) -> MICHAEL HASAN | B7: 2WSL: Springfield | C7: 46296 | D7: MICHAEL HASAN (130047) | E7: 46296.495 | F7: 46296.826 | G7: 7:20 | H7: 5:50 | I7: 1:30 | J7: 0:37 | K7: Y
A8: =TRIM(_xlfn.TEXTBEFORE(D8,"(")) -> JAYLON TAYLOR | B8: 2WSL: Springfield | C8: 46296 | D8: JAYLON TAYLOR (122451) | E8: 46296.381 | F8: 46296.744 | G8: 8:42 | H8: 7:36 | I8: 1:6 | J8: 0:0 | K8: Y
A9: =TRIM(_xlfn.TEXTBEFORE(D9,"(")) -> RICCO CURRIE | B9: 2WSL: Springfield | C9: 46296 | D9: RICCO CURRIE (126768) | E9: 1 | F9: 1 | G9: 0:0 | H9: 0:0 | I9: 0:0 | J9: 0:0 | K9: Y
A10: =TRIM(_xlfn.TEXTBEFORE(D10,"(")) -> EMILY DRAZER | B10: 2WSL: Springfield | C10: 46296 | D10: EMILY DRAZER (121778) | E10: 46296.501 | F10: 46296.849 | G10: 8:22 | H10: 6:31 | I10: 1:51 | J10: 0:0 | K10: Y
A11: =TRIM(_xlfn.TEXTBEFORE(D11,"(")) -> ALYSIA MEFFORD | B11: 2WSF: Xenia | C11: 46296 | D11: ALYSIA MEFFORD (127863) | E11: 46296.492 | F11: 46296.844 | G11: 8:28 | H11: 7:58 | I11: 0:30 | J11: 0:0 | K11: Y
A12: =TRIM(_xlfn.TEXTBEFORE(D12,"(")) -> KYRA BOBBITT | B12: 2WSF: Xenia | C12: 46296 | D12: KYRA BOBBITT (128542) | E12: 1 | F12: 1 | G12: 0:0 | H12: 0:0 | I12: 0:0 | J12: 0:0 | K12: Y
A13: =TRIM(_xlfn.TEXTBEFORE(D13,"(")) -> CHRISTOPHER MEFFORD | B13: 2WSF: Xenia | C13: 46296 | D13: CHRISTOPHER MEFFORD (112574) | E13: 46296.392 | F13: 46296.719 | G13: 7:42 | H13: 5:12 | I13: 2:30 | J13: 0:9 | K13: Y
... A11449: =TRIM(_xlfn.TEXTBEFORE(D11449,"(")) -> SHANITA MOBIN | B11449: 0118: Eastchase | C11449: 46301 | D11449: SHANITA MOBIN (126151) | E11449: 1 | F11449: 1 | G11449: 0:0 | H11449: 0:0 | I11449: 0:0 | J11449: 0:0 | K11449: Y
A11450: =TRIM(_xlfn.TEXTBEFORE(D11450,"(")) -> #N/A
A11451: =TRIM(_xlfn.TEXTBEFORE(D11451,"(")) -> #N/A
A11452: =TRIM(_xlfn.TEXTBEFORE(D11452,"(")) -> JAIDYN SCHILLING | B11452: 4CSN: Hot Springs | C11452: 46302 | D11452: JAIDYN SCHILLING (115696) | E11452: 46302.418 | F11452: 46302.857 | G11452: 10:32 | H11452: 7:0 | I11452: 3:32 | J11452: 0:0 | K11452: Y
A11453: =TRIM(_xlfn.TEXTBEFORE(D11453,"(")) -> JENNA WHITTAMORE | B11453: 4CSN: Hot Springs | C11453: 46302 | D11453: JENNA WHITTAMORE (129738) | E11453: 46302.375 | F11453: 46302.661 | G11453: 6:51 | H11453: 5:6 | I11453: 1:45 | J11453: 0:0 | K11453: Y
A11454: =TRIM(_xlfn.TEXTBEFORE(D11454,"(")) -> SHELBI HALL | B11454: 4CSN: Hot Springs | C11454: 46302 | D11454: SHELBI HALL (129683) | E11454: 46302.43 | F11454: 46302.602 | G11454: 3:54 | H11454: 3:54 | I11454: 0:0 | J11454: 0:14 | K11454: Y
A11455: =TRIM(_xlfn.TEXTBEFORE(D11455,"(")) -> CAINON WILLIAMS | B11455: 4CSN: Hot Springs | C11455: 46302 | D11455: CAINON WILLIAMS (130246) | E11455: 46302.474 | F11455: 46302.857 | G11455: 9:10 | H11455: 8:19 | I11455: 0:51 | J11455: 0:0 | K11455: Y
A11456: =TRIM(_xlfn.TEXTBEFORE(D11456,"(")) -> KISHA MACON | B11456: 4CST: Little Rock | C11456: 46302 | D11456: KISHA MACON (130420) | E11456: 46302.5 | F11456: 46302.843 | G11456: 8:13 | H11456: 6:39 | I11456: 1:34 | J11456: 0:0 | K11456: Y
A11457: =TRIM(_xlfn.TEXTBEFORE(D11457,"(")) -> MARCUS ROBINSON | B11457: 4CST: Little Rock | C11457: 46302 | D11457: MARCUS ROBINSON (130456) | E11457: 46302.375 | F11457: 46302.567 | G11457: 3:56 | H11457: 3:47 | I11457: 0:9 | J11457: 0:40 | K11457: Y
A11458: =TRIM(_xlfn.TEXTBEFORE(D11458,"(")) -> DENNIS GARDNER | B11458: 4CST: Little Rock | C11458: 46302 | D11458: DENNIS GARDNER (121326) | E11458: 46302.402 | F11458: 46302.857 | G11458: 9:52 | H11458: 8:26 | I11458: 1:26 | J11458: 1:3 | K11458: Y
A11459: =TRIM(_xlfn.TEXTBEFORE(D11459,"(")) -> JESS DITTRICH | B11459: 4CST: Little Rock | C11459: 46302 | D11459: JESS DITTRICH (111747) | E11459: 46302.434 | F11459: 46302.65 | G11459: 4:23 | H11459: 2:5 | I11459: 2:18 | J11459: 0:48 | K11459: Y
A11460: =TRIM(_xlfn.TEXTBEFORE(D11460,"(")) -> TRACIE KYLE | B11460: 4CST: Little Rock | C11460: 46302 | D11460: TRACIE KYLE (126385) | E11460: 46302.375 | F11460: 46302.65 | G11460: 6:23 | H11460: 3:59 | I11460: 2:24 | J11460: 0:13 | K11460: Y
A11461: =TRIM(_xlfn.TEXTBEFORE(D11461,"(")) -> WILLIAM HILL | B11461: 4CSM: Pine Bluff | C11461: 46302 | D11461: WILLIAM HILL (120933) | E11461: 46302.383 | F11461: 46302.675 | G11461: 6:24 | H11461: 5:19 | I11461: 1:5 | J11461: 0:37 | K11461: Y
A11462: =TRIM(_xlfn.TEXTBEFORE(D11462,"(")) -> JESHELLE NIEVES | B11462: 4CSM: Pine Bluff | C11462: 46302 | D11462: JESHELLE NIEVES (130212) | E11462: 46302.395 | F11462: 46302.707 | G11462: 6:36 | H11462: 6:12 | I11462: 0:24 | J11462: 0:54 | K11462: Y
A11463: =TRIM(_xlfn.TEXTBEFORE(D11463,"(")) -> MICHELLE STUART | B11463: 4CSM: Pine Bluff | C11463: 46302 | D11463: MICHELLE STUART (129556) | E11463: 46302.418 | F11463: 46302.848 | G11463: 9:33 | H11463: 8:39 | I11463: 0:54 | J11463: 0:46 | K11463: Y
... A12642: =TRIM(_xlfn.TEXTBEFORE(D12642,"(")) -> SABRINA BARRIENTOS | B12642: 5441: South Bibb | C12642: 46302 | D12642: SABRINA BARRIENTOS (126245) | E12642: 46302.386 | F12642: 46302.583 | G12642: 4:44 | H12642: 4:5 | I12642: 0:39 | J12642: 0:0 | K12642: Y
